telegram.vendor.ptb_urllib3.urllib3.connectionpool - WARNING - Retrying (Retry(total=2, connect=None, read=None, redirect=None)) after connection broken by 'ConnectTimeoutError(<telegram.vendor.ptb_urllib3.urllib3.contrib.socks.SOCKSHTTPSConnection object at 0x0000019383046B08>, 'Connection to api.telegram.org timed out. (connect timeout=5.0)')': /bot987896247:AAGZL6tIafSKsgddyaHKmoK91ZTBNX5sSec/getMe
telegram.vendor.ptb_urllib3.urllib3.connectionpool - WARNING - Retrying (Retry(total=1, connect=None, read=None, redirect=None)) after connection broken by 'ConnectTimeoutError(<telegram.vendor.ptb_urllib3.urllib3.contrib.socks.SOCKSHTTPSConnection object at 0x0000019383055048>, 'Connection to api.telegram.org timed out. (connect timeout=5.0)')': /bot987896247:AAGZL6tIafSKsgddyaHKmoK91ZTBNX5sSec/getMe
telegram.vendor.ptb_urllib3.urllib3.connectionpool - WARNING - Retrying (Retry(total=0, connect=None, read=None, redirect=None)) after connection broken by 'ConnectTimeoutError(<telegram.vendor.ptb_urllib3.urllib3.contrib.socks.SOCKSHTTPSConnection object at 0x0000019383055108>, 'Connection to api.telegram.org timed out. (connect timeout=5.0)')': /bot987896247:AAGZL6tIafSKsgddyaHKmoK91ZTBNX5sSec/getMe
telegram.ext.updater - INFO - Received signal 2 (SIGINT), stopping...
telegram.ext.updater - INFO - Received signal 2 (SIGINT), stopping...
telegram.ext.updater - INFO - Received signal 2 (SIGINT), stopping...
telegram.ext.updater - INFO - Received signal 2 (SIGINT), stopping...
telegram.ext.dispatcher - ERROR - No error handlers are registered, logging exception.
Traceback (most recent call last):
  File "C:\Users\sobar\AppData\Local\Programs\Python\Python37\lib\site-packages\telegram\ext\dispatcher.py", line 372, in process_update
    handler.handle_update(update, self, check, context)
  File "C:\Users\sobar\AppData\Local\Programs\Python\Python37\lib\site-packages\telegram\ext\handler.py", line 120, in handle_update
    return self.callback(dispatcher.bot, update, **optional_args)
  File "ephem_bot.py", line 50, in planet
    update.message.reply_text(answer)
UnboundLocalError: local variable 'answer' referenced before assignment
telegram.ext.dispatcher - ERROR - No error handlers are registered, logging exception.
Traceback (most recent call last):
  File "C:\Users\sobar\AppData\Local\Programs\Python\Python37\lib\site-packages\telegram\ext\dispatcher.py", line 372, in process_update
    handler.handle_update(update, self, check, context)
  File "C:\Users\sobar\AppData\Local\Programs\Python\Python37\lib\site-packages\telegram\ext\handler.py", line 120, in handle_update
    return self.callback(dispatcher.bot, update, **optional_args)
  File "ephem_bot.py", line 50, in planet
    update.message.reply_text(answer)
UnboundLocalError: local variable 'answer' referenced before assignment
telegram.ext.updater - INFO - Received signal 2 (SIGINT), stopping...
telegram.ext.dispatcher - ERROR - No error handlers are registered, logging exception.
Traceback (most recent call last):
  File "C:\Users\sobar\AppData\Local\Programs\Python\Python37\lib\site-packages\telegram\ext\dispatcher.py", line 372, in process_update
    handler.handle_update(update, self, check, context)
  File "C:\Users\sobar\AppData\Local\Programs\Python\Python37\lib\site-packages\telegram\ext\handler.py", line 120, in handle_update
    return self.callback(dispatcher.bot, update, **optional_args)
  File "ephem_bot.py", line 47, in planet
    answer = ephem.constellation(now)
ValueError: the sequence specifying a position must have exactly two coordinates
telegram.ext.dispatcher - ERROR - No error handlers are registered, logging exception.
Traceback (most recent call last):
  File "C:\Users\sobar\AppData\Local\Programs\Python\Python37\lib\site-packages\telegram\ext\dispatcher.py", line 372, in process_update
    handler.handle_update(update, self, check, context)
  File "C:\Users\sobar\AppData\Local\Programs\Python\Python37\lib\site-packages\telegram\ext\handler.py", line 120, in handle_update
    return self.callback(dispatcher.bot, update, **optional_args)
  File "ephem_bot.py", line 47, in planet
    answer = ephem.constellation(now)
ValueError: the sequence specifying a position must have exactly two coordinates
telegram.ext.updater - INFO - Received signal 2 (SIGINT), stopping...
telegram.ext.updater - INFO - Received signal 2 (SIGINT), stopping...
telegram.ext.updater - INFO - Received signal 2 (SIGINT), stopping...
telegram.ext.updater - INFO - Received signal 2 (SIGINT), stopping...
